Workbook

Sheet 5ªfeira
C2: PLANO DIÁRIO PARA A LINHA DE FATIADOS - SEMANA 14 / 2026 | L2: SUPPLY CHAIN / PLAN PRODUÇÃO
L4: 46113.665
H7: 5ªfeira | J7: 46114 | AA7: 0.33333333 | AB7: simular produção
A9: LINHA | B9: CÓDIGO | C9: VERSÃO | E9: PI | F9: Filme Sup | G9: Filme I | H9: PRODUTO | I9: OP | J9: NOTAS DE PLANEAMENTO | K9: Kg Entrada | L9: Un Finais | M9: Nºcaixas | N9: kg/un | O9: Plano kg | P9: Real kg | Q9: ABS | R9: T. Horas | T9: Horas | U9: Un/Ciclos | V9: mt | W9: Cód caixas | X9: Un/Caixa | AA9: kilos / hora | AB9: horas até final | AC9: kilos que faltam
A11: I | B11: 38095 | C11: PV01 | D11: 1 | E11: 1902829 | F11: 4041556 | G11: 4037827 | H11: CHOPPED PORK 95G 1E CJ*12 | I11: 12164193 | K11: 2365.5914 | L11: 23157 | M11: 1929.75 | N11: 0.095 | O11: 2200 | Q11: 2200 | R11: 6.8477544 | S11: 16 | T11: 0.66666667 | U11: #N/A | V11: #N/A | W11: 4036583 | X11: 12 | AA11: 321.2732 | AB11: 15 | AC11: 2200
A12: I | D12: 1 | Q12: 0 | S12: 23.597754 | T12: 0.98323977 | AA12: 0 | AB12: #REF! | AC12: 0
A13: I | D13: 1 | Q13: 0 | S13: #VALUE! | AA13: 0 | AB13: #REF! | AC13: 0
A14: I | D14: 1 | Q14: 0 | S14: #VALUE! | AA14: 0 | AB14: #REF! | AC14: 0
A15: I | D15: 1 | Q15: 0 | S15: #VALUE! | AA15: 0 | AB15: #REF! | AC15: 0
A16: I | D16: 1 | Q16: 0 | S16: #VALUE! | AA16: 0 | AB16: #REF! | AC16: 0
A17: I | D17: 1 | Q17: 0 | S17: #VALUE! | AA17: 0 | AB17: #REF! | AC17: 0
A18: I | D18: 1 | Q18: 0 | S18: #VALUE! | AA18: 0 | AB18: #REF! | AC18: 0
A19: I | D19: 1 | Q19: 0 | S19: #VALUE! | AA19: 0 | AB19: #REF! | AC19: 0
A20: I | D20: 1 | Q20: 0 | S20: #VALUE! | AA20: 0 | AB20: #REF! | AC20: 0
A21: I | D21: 1 | Q21: 0 | S21: #VALUE! | AA21: 0 | AB21: #REF! | AC21: 0
A22: I | D22: 1 | Q22: 0 | S22: #VALUE! | AA22: 0 | AB22: #REF! | AC22: 0
A23: I | D23: 1 | Q23: 0 | S23: #VALUE! | AA23: 0 | AB23: #REF! | AC23: 0
A24: I | Q24: 0 | S24: #VALUE! | AA24: 0 | AB24: #REF! | AC24: 0
Q25: 0 | S25: #VALUE! | AA25: 0 | AB25: #REF! | AC25: 0
Q26: 0 | AA26: 0 | AB26: #REF! | AC26: 0
A27: II | B27: 18125 | C27: PV02 | D27: 2 | E27: 1901167 | F27: 4012689 | G27: 4013635 | H27: FAT FIAM P EX 3X350G 3XGAS FSR | I27: 12164104 | K27: 1814.2629 | L27: 1619 | M27: 539.66667 | N27: 1.05 | O27: 1700 | Q27: 1700 | R27: 4.1251723 | S27: 3 | T27: 0.125 | U27: 2 | V27: 418.92857 | W27: 4027464 | X27: 3 | AA27: 412.104 | AB27: 0 | AC27: 0
A28: II | B28: 41835 | C28: PV01 | D28: 2 | E28: 1905643 | F28: 4043188 | G28: 4044028 | H28: FAT F PERNA EXTRA GAS 11X120G NB | I28: 12164105 | K28: 615.05094 | L28: 4583 | M28: 416.63636 | N28: 0.12 | O28: 550 | Q28: 550 | R28: 2.4229075 | S28: 7.8751723 | T28: 0.32813218 | U28: #N/A | V28: #N/A | W28: 4045334 | X28: 11 | AA28: 227 | AB28: #REF! | AC28: #REF!
A29: II | B29: 41843 | C29: PV01 | D29: 2 | E29: 1905643 | F29: 4043188 | G29: 4044028 | H29: FAT F PERNA EXTRA GAS 8X220G NB | I29: 12164106 | J29: rubis | K29: 277.35323 | L29: 1136 | M29: 142 | N29: 0.22 | O29: 250 | Q29: 250 | R29: 0.96525097 | S29: 10.29808 | T29: 0.42908666 | U29: #N/A | V29: #N/A | W29: 4045334 | X29: 8 | AA29: 259 | AB29: #REF! | AC29: 250
A30: II | B30: 18354 | C30: PV2 | D30: 2 | E30: 1901169 | F30: 4022166 | G30: 4013192 | H30: FAT ECON FIAMBRE 14X100G NBR | I30: 12164107 | J30: rubis | K30: 547.00547 | L30: 5000 | M30: 357.14286 | N30: 0.1 | O30: 500 | Q30: 500 | R30: 2.4952864 | S30: 11.263331 | T30: 0.46930545 | U30: 6 | V30: 431.25 | W30: 4022088 | X30: 14 | AA30: 200.3778 | AB30: #REF! | AC30: 500
A31: II | B31: 28667 | C31: PV2 | D31: 2 | E31: 1901169 | F31: 4022166 | G31: 4013192 | H31: FAT ECON S SELO FIAMBRE 14X100G NB | I31: 12164108 | K31: 243.94053 | L31: 2250 | M31: 160.71429 | N31: 0.1 | O31: 225 | Q31: 225 | R31: 1.4355012 | S31: 13.758617 | T31: 0.57327571 | U31: 6 | V31: 194.0625 | W31: 4022088 | X31: 14 | AA31: 156.73968 | AB31: #REF! | AC31: 225
A32: II | B32: 33523 | C32: PV04 | D32: 2 | E32: 1901152 | F32: 4022166 | G32: 4013192 | H32: FAT PAIO YORK S/SELO GAS 12X90G ECON NB | I32: 12164109 | K32: 159.91471 | L32: 1666 | M32: 138.83333 | N32: 0.09 | O32: 150 | Q32: 150 | R32: 0.91371263 | S32: 16.694118 | T32: 0.69558826 | U32: 6 | V32: 143.75 | W32: 4022088 | X32: 12 | AA32: 164.1654 | AB32: #REF! | AC32: 150
A33: II | B33: 41846 | C33: PV01 | D33: 2 | E33: 1901414 | F33: 4046002 | G33: 4044028 | H33: FAT PEITO FRANGO GAS 12X120G FL CF | I33: 12164110 | K33: 483.89632 | L33: 3750 | M33: 312.5 | N33: 0.12 | O33: 450 | Q33: 450 | R33: 1.3609442 | S33: 17.607831 | T33: 0.73365962 | U33: #N/A | V33: #N/A | W33: 4047926 | X33: 12 | AA33: 330.6528 | AB33: #REF! | AC33: 450
A34: II | B34: 41845 | C34: PV01 | D34: 2 | E34: 1907601 | F34: 4046002 | G34: 4044028 | H34: FAT PEITO PERU GAS 12X120G FL CF | I34: 12164194 | K34: 720.71913 | L34: 5625 | M34: 468.75 | N34: 0.12 | O34: 675 | Q34: 675 | R34: 3.4797402 | S34: 18.968775 | T34: 0.79036563 | U34: #N/A | V34: #N/A | W34: 4047926 | X34: 12 | AA34: 193.98 | AB34: #REF! | AC34: 675
A35: II | D35: 2 | Q35: 0 | S35: 23.528515 | T35: 0.98035481 | AA35: 0 | AB35: #REF! | AC35: 0
A36: II | D36: 2 | Q36: 0 | S36: #VALUE! | AA36: 0 | AB36: #REF! | AC36: 0
A37: II | D37: 2 | Q37: 0 | S37: #VALUE! | AA37: 0 | AB37: #REF! | AC37: 0
A38: II | D38: 2 | Q38: 0 | S38: #VALUE! | AA38: 0 | AB38: #REF! | AC38: 0
D39: 2 | Q39: 0 | S39: #VALUE! | AA39: 0 | AB39: #REF! | AC39: 0
Q40: 0
Q41: 0 | AA41: 0
A42: III | B42: 22544 | C42: PV01 | D42: 3 | E42: 1907134 | F42: 4017478 | G42: 4013192 | H42: FIN F PERNA EXT GAS 8X110G CDT NB | I42: 12164111 | J42: rubis | K42: 450.43973 | L42: 3654 | M42: 456.75 | N42: 0.11 | O42: 402 | Q42: 402 | R42: 1.9851299 | S42: 3 | T42: 0.125 | U42: 6 | V42: 315.20455 | W42: 4022088 | X42: 8 | AA42: 202.50564
A43: III | B43: 24378 | C43: PV1 | D43: 3 | E43: 1901678 | F43: 4017478 | G43: 4013192 | H43: FIN PEITO FRANGO GAS 8X110G CDT NB | I43: 12164112 | K43: 627.04196 | L43: 5272 | M43: 659 | N43: 0.11 | O43: 580 | Q43: 580 | R43: 3.4160054 | S43: 5.7351299 | T43: 0.23896374 | U43: 6 | V43: 454.77273 | W43: 4022088 | X43: 8 | AA43: 169.78896
A44: III | B44: 37046 | C44: PV01 | D44: 3 | E44: 1901460 | F44: 4039385 | G44: 4013192 | H44: FIN FIAMBRE FRANGO GAS 8X140G ECON NB | I44: 12164113 | K44: 217.90636 | L44: 1428 | M44: 178.5 | N44: 0.14 | O44: 200 | Q44: 200 | R44: 0.89698479 | S44: 9.1511352 | T44: 0.3812973 | U44: 6 | V44: 123.21429 | W44: 4022086 | X44: 8 | AA44: 222.96922
A45: III | B45: 41839 | C45: PV02 | D45: 3 | E45: 1905643 | F45: 4040832 | G45: 4044028 | H45: FIN F PERNA EXTRA GAS 6X220G NB | I45: 12164114 | J45: rubis | K45: 445.77117 | L45: 1836 | M45: 306 | N45: 0.22 | O45: 404 | Q45: 404 | R45: 1.1681435 | S45: 10.04812 | T45: 0.41867167 | U45: #N/A | V45: #N/A | W45: 4045734 | X45: 6 | AA45: 345.84792
A46: III | B46: 41844 | C46: PV02 | D46: 3 | E46: 1905643 | F46: 4040832 | G46: 4044028 | H46: FIN F PERNA EXTRA GAS 8X120G NB | I46: 12164115 | J46: rubis | K46: 991.43862 | L46: 7500 | M46: 937.5 | N46: 0.12 | O46: 900 | Q46: 900 | R46: 4.2782579 | S46: 11.216264 | T46: 0.46734431 | U46: #N/A | V46: #N/A | W46: 4045734 | X46: 8 | AA46: 210.366
...

Sheet Nec_5ª
A1: NECESSIDADES PARA A LINHA DE FATIADOS | F1: SUPPLY CHAIN PLAN PRODUÇÃO
A3: DATA: | B3: ='5ªfeira'!J7 -> 46114
B4: ='5ªfeira'!B9 -> CÓDIGO
A7: MAT. PRIMA PRINCIPAL
A9: CÓDIGO | B9: PRODUTO INTERMÉDIO P/FATIAR | C9: kg | D9: Paletes | E9: Gavetas | F9: Real
A11: 1904002 | B11: SP1 FIAM PERN EXT P/FAT/SLI NB | C11: =SUMIF('5ªfeira'!$E$11:$K$117,A11,'5ªfeira'!$K$11:$K$109) -> 0 | D11: =INT(C11/432) -> 0 | E11: =(((C11/432)-D11)*25) -> 0 | F11: (*)
A12: 1904003 | B12: SP1 FIAMBRE PÁ P/FAT NB | C12: =SUMIF('5ªfeira'!$E$11:$K$117,A12,'5ªfeira'!$K$11:$K$109) -> 0 | D12: =INT(C12/432) -> 0 | E12: =(((C12/432)-D12)*25) -> 0
A13: 1904004 | B13: SP1 FIAMBRE PÁ P/FAT MP | C13: =SUMIF('5ªfeira'!$E$11:$K$117,A13,'5ªfeira'!$K$11:$K$109) -> 0 | D13: =INT(C13/432) -> 0 | E13: =(((C13/432)-D13)*25) -> 0
A14: 1901167 | B14: Mpp Fiambre Perna Extra | C14: =SUMIF('5ªfeira'!$E$11:$K$117,A14,'5ªfeira'!$K$11:$K$109) -> 1814.2629 | D14: =INT(C14/432) -> 4 | E14: =(((C14/432)-D14)*25) -> 4.9920642
A15: 1901482 | B15: SP1 FIAMB PERNA EXTRA P/FAT CDT NB | C15: =SUMIF('5ªfeira'!$E$11:$K$117,A15,'5ªfeira'!$K$11:$K$109) -> 0 | D15: =INT(C15/432) -> 0 | E15: =(((C15/432)-D15)*25) -> 0
A16: 1903048 | B16: SP1 FIAMB P EXT 11:11 P/FAT MP | C16: =SUMIF('5ªfeira'!$E$11:$K$117,A16,'5ªfeira'!$K$11:$K$109) -> 0 | D16: =INT(C16/432) -> 0 | E16: =(((C16/432)-D16)*25) -> 0
A17: 1904349 | B17: SP1 FIAMB P EXT P/FAT MERCADONA | C17: =SUMIF('5ªfeira'!$E$11:$K$117,A17,'5ªfeira'!$K$11:$K$109) -> 2946.3262 | D17: =INT(C17/432) -> 6 | E17: =(((C17/432)-D17)*25) -> 20.50499
A18: 1907179 | B18: SP1 FIAM PERN EXT BRAS P/FAT NB BA | C18: =SUMIF('5ªfeira'!$E$11:$K$117,A18,'5ªfeira'!$K$11:$K$109) -> 0 | D18: =INT(C18/432) -> 0 | E18: =(((C18/432)-D18)*25) -> 0
A19: 1905278 | B19: SP1 FIAMB P EXT P/FAT CTE | C19: =SUMIF('5ªfeira'!$E$11:$K$117,A19,'5ªfeira'!$K$11:$K$109) -> 3733.7452 | D19: =INT(C19/432) -> 8 | E19: =(((C19/432)-D19)*25) -> 16.073217
A20: 1905643 | B20: SP1 FIAM PERN EXT P/FAT NB - BA | C20: =SUMIF('5ªfeira'!$E$11:$K$117,A20,'5ªfeira'!$K$11:$K$109) -> 2329.614 | D20: =INT(C20/432) -> 5 | E20: =(((C20/432)-D20)*25) -> 9.815623
A21: 1906346 | B21: SP1 FIAMB P EXT P/FAT CTE (17KG) | C21: =SUMIF('5ªfeira'!$E$11:$K$117,A21,'5ªfeira'!$K$11:$K$109) -> 0 | D21: =INT(C21/432) -> 0 | E21: =(((C21/432)-D21)*25) -> 0
A22: 1907134 | B22: SP1 FIAMB PERNA EXTRA P/FAT CDT NB - BA | C22: =SUMIF('5ªfeira'!$E$11:$K$117,A22,'5ªfeira'!$K$11:$K$109) -> 450.43973 | D22: =INT(C22/432) -> 1 | E22: =(((C22/432)-D22)*25) -> 1.0671143
A23: 1907444 | B23: SP1 FIAMB P EXT FL P/FAT CF | C23: =SUMIF('5ªfeira'!$E$11:$K$117,A23,'5ªfeira'!$K$11:$K$109) -> 0 | D23: =INT(C23/432) -> 0 | E23: =(((C23/432)-D23)*25) -> 0
... A28: 1902009 | B28: SP3 PAIO DO LOMBO P/FATIAR | C28: =SUMIF('5ªfeira'!$E$11:$K$117,A28,'5ªfeira'!$K$11:$K$109) -> 169.87983 | D28: =INT(C28/432) -> 0 | E28: =(((C28/432)-D28)*25) -> 9.8310088
A30: 1901158 | B30: Chourição Bakemark para Fatiar | C30: =SUMIF('5ªfeira'!$E$11:$K$117,A30,'5ªfeira'!$K$11:$K$109) -> 0 | E30: (*) Paletes de 480kg e não 432kg
A31: 1901157 | B31: Chourição para Fatiar NBR | C31: =SUMIF('5ªfeira'!$E$11:$K$117,A31,'5ªfeira'!$K$11:$K$109) -> 0
A32: 1901149 | B32: Toucinho S/courato FSR | C32: =SUMIF('5ªfeira'!$E$11:$K$117,A32,'5ªfeira'!$K$11:$K$109) -> 0
A33: 1901156 | B33: Mpp Chourição para Fatiar | C33: =SUMIF('5ªfeira'!$E$11:$K$117,A33,'5ªfeira'!$K$11:$K$109) -> 3496.7613
A34: 8401 | B34: SP2 CHOURIÇÃO EXT T ESPANHOL P | C34: =SUMIF('5ªfeira'!$E$11:$K$117,A34,'5ªfeira'!$K$11:$K$109) -> 0
A36: 6082 | B36: Presunto FSR | C36: =SUMIF('5ªfeira'!$E$11:$K$117,A36,'5ªfeira'!$K$11:$K$109) -> 0
A37: 1903201 | B37: SP3 PEITO FRANGO ASSADO P/FAT CF | C37: =SUMIF('5ªfeira'!$E$11:$K$117,A37,'5ªfeira'!$K$11:$K$109) -> 0
A38: 1903202 | B38: SP3 PEITO FRANGO ALHO P/FAT CF | C38: =SUMIF('5ªfeira'!$E$11:$K$117,A38,'5ªfeira'!$K$11:$K$109) -> 0
A39: 1902621 | B39: JAMON 1ª RED SAL LONCH 18x11 1500MM | C39: =SUMIF('5ªfeira'!$E$11:$K$117,A39,'5ªfeira'!$K$11:$K$109) -> 0
A40: 1902840 | B40: MORTAD PAVO CUIDATE LONCH. D110 1,5M | C40: =SUMIF('5ªfeira'!$E$11:$K$117,A40,'5ªfeira'!$K$11:$K$109) -> 0
A41: 1902858 | B41: CHOPPED PAVO CUIDATE D110 1500MM | C41: =SUMIF('5ªfeira'!$E$11:$K$117,A41,'5ªfeira'!$K$11:$K$109) -> 0
A42: 1903298 | B42: SP3 PEITO PERU C/VEGET P/FAT CF | C42: =SUMIF('5ªfeira'!$E$11:$K$117,A42,'5ªfeira'!$K$11:$K$109) -> 0
A43: 1903659 | B43: P.PAVO SF RED SAL LONCH 11X11 1500MM | C43: =SUMIF('5ªfeira'!$E$11:$K$117,A43,'5ªfeira'!$K$11:$K$109) -> 0
... A78: 1901164 | B78: CHOURIÇÃO P/FAT ECON | C78: =SUMIF('5ªfeira'!$E$11:$K$117,A78,'5ªfeira'!$K$11:$K$109) -> 1049.2863
A81: CÓDIGO | B81: REFERÊNCIA | C81: mt/rolo | D81: mt | E81: Rolos
A83: 4012689 | B83: Sup.Transparente 65 um | C83: 550 | D83: =SUMIF(#REF!,A83,#REF!) -> #REF! | E83: =D83/C83 -> #REF!
A84: 4013501 | B84: Sup.Transparente fresquissimos | C84: 550 | D84: =SUMIF(#REF!,A84,#REF!) -> #REF! | E84: =D84/C84 -> #REF!
A85: 4012770 | B85: Sup Bordaux 3x2 65 um | C85: 550 | D85: =SUMIF(#REF!,A85,#REF!) -> #REF! | E85: =D85/C85 -> #REF!
A86: 4012767 | B86: Sup Amarelo 3x2 65 um | C86: 550 | D86: =SUMIF(#REF!,A86,#REF!) -> #REF! | E86: =D86/C86 -> #REF!
A87: 4012768 | B87: Sup Bordaux dg 2x2 65 um | C87: 550 | D87: =SUMIF(#REF!,A87,#REF!) -> #REF! | E87: =D87/C87 -> #REF!
A88: 4012794 | B88: Sup Amarelo 2x2 65 um | C88: 550 | D88: =SUMIF(#REF!,A88,#REF!) -> #REF! | E88: =D88/C88 -> #REF!
...
